Workbook

Sheet Sheet1

Sheet Forecast vs Actuals
O1: F4W | R1: F8W | W1: IM FCST RR | AJ1: IM FCST YoY | AW1: OP FCST RR | BJ1: OP FCST YoY | BW1: IM F8W GAP | CD1: IM F4W GAP
W2: =W6 -> 46103 | X2: =X6 -> 46110 | Y2: =Y6 -> 46117 | Z2: =Z6 -> 46124 | AA2: =AA6 -> 46131 | AB2: =AB6 -> 46138 | AC2: =AC6 -> 46145 | AD2: =AD6 -> 46152 | ... AH2: =AH6 -> 46180 | AW2: =AW6 -> 46103 | AX2: =AX6 -> 46110 | AY2: =AY6 -> 46117 | AZ2: =AZ6 -> 46124 | BA2: =BA6 -> 46131 | BB2: =BB6 -> 46138 | BC2: =BC6 -> 46145 | BD2: =BD6 -> 46152 | ... BH2: =BH6 -> 46180
E3: LY | L3: L6W RR | M3: L6W YoY | O3: IM | P3: IM | R3: IM | S3: IM | T3: AE | U3: AE | W3: CW+1 | X3: CW+2 | Y3: CW+3 | Z3: CW+4 | AA3: CW+5 | AB3: CW+6 | AC3: CW+7 | AD3: CW+8 | AE3: CW+9 | AF3: CW+10 | AG3: CW+11 | AH3: CW+12 | AJ3: CW+1 | AK3: CW+2 | AL3: CW+3 | AM3: CW+4 | AN3: CW+5 | AO3: CW+6 | AP3: CW+7 | AQ3: CW+8 | AR3: CW+9 | AS3: CW+10 | AT3: CW+11 | AU3: CW+12 | AW3: CW+1 | AX3: CW+2 | AY3: CW+3 | AZ3: CW+4 | BA3: CW+5 | BB3: CW+6 | BC3: CW+7 | BD3: CW+8 | BE3: CW+9 | BF3: CW+10 | BG3: CW+11 | BH3: CW+12 | BJ3: CW+1 | BK3: CW+2 | BL3: CW+3 | BM3: CW+4 | BN3: CW+5 | BO3: CW+6 | BP3: CW+7 | BQ3: CW+8 | BR3: CW+9 | BS3: CW+10 | BT3: CW+11 | BU3: CW+12 | BW3: LY | BX3: F8W YoY | BY3: L6W | BZ3: F8W | CA3: YoY Contribution | CD3: LY | CE3: F4W YoY | CF3: L6W | CG3: F4W | CH3: YoY Contribution
B4: ALL BRANDS | C4: Cohort | D4: PATTERN AMERICAS | E4: =SUM(E8:E537) -> 1169397 | F4: =SUM(F8:F537) -> 1639556 | G4: =SUM(G8:G537) -> 1625930 | H4: =SUM(H8:H537) -> 1625180 | I4: =SUM(I8:I537) -> 1625697 | J4: =SUM(J8:J537) -> 1640755 | K4: =SUM(K8:K537) -> 1667790 | L4: =SUM(L8:L537) -> 1637239 | M4: =(L4-E4)/E4 -> 0.40007115 | O4: =AVERAGE(W4:Z4) -> 1720832.8 | P4: =CE4 -> 0.44180583 | R4: =AVERAGE(W4:AD4) -> 1730051 | S4: =BX4 -> 0.42168532 | T4: =AVERAGE(AW4:BD4) -> 1478394.4 | U4: =#REF! -> #REF! | W4: =SUM(W8:W537) -> 1749250 | X4: =SUM(X8:X537) -> 1715561 | Y4: =SUM(Y8:Y537) -> 1706954 | Z4: =SUM(Z8:Z537) -> 1711566 | AA4: =SUM(AA8:AA537) -> 1717107 | AB4: =SUM(AB8:AB537) -> 1747078 | AC4: =SUM(AC8:AC537) -> 1762487 | AD4: =SUM(AD8:AD537) -> 1730405 | ... AH4: =SUM(AH8:AH537) -> 1750245 | AJ4: =(W4-SUMIFS('Forecast Data'!$H:$H,'Forecast Data'!$B:$B,$B4,'Forecast Data'!$C:$C,AJ$6))/SUMIFS('Forecast Data'!$H:$H,'Forecast Data'!$B:$B,$B4,'Forecast Data'!$C:$C,AJ$6) -> 0.4623733 | AK4: =(X4-SUMIFS('Forecast Data'!$H:$H,'Forecast Data'!$B:$B,$B4,'Forecast Data'!$C:$C,AK$6))/SUMIFS('Forecast Data'!$H:$H,'Forecast Data'!$B:$B,$B4,'Forecast Data'!$C:$C,AK$6) -> 0.42914588 | AL4: =(Y4-SUMIFS('Forecast Data'!$H:$H,'Forecast Data'!$B:$B,$B4,'Forecast Data'!$C:$C,AL$6))/SUMIFS('Forecast Data'!$H:$H,'Forecast Data'!$B:$B,$B4,'Forecast Data'!$C:$C,AL$6) -> 0.45917824 | AM4: =(Z4-SUMIFS('Forecast Data'!$H:$H,'Forecast Data'!$B:$B,$B4,'Forecast Data'!$C:$C,AM$6))/SUMIFS('Forecast Data'!$H:$H,'Forecast Data'!$B:$B,$B4,'Forecast Data'!$C:$C,AM$6) -> 0.41719128 | AN4: =(AA4-SUMIFS('Forecast Data'!$H:$H,'Forecast Data'!$B:$B,$B4,'Forecast Data'!$C:$C,AN$6))/SUMIFS('Forecast Data'!$H:$H,'Forecast Data'!$B:$B,$B4,'Forecast Data'!$C:$C,AN$6) -> 0.40656663 | AO4: =(AB4-SUMIFS('Forecast Data'!$H:$H,'Forecast Data'!$B:$B,$B4,'Forecast Data'!$C:$C,AO$6))/SUMIFS('Forecast Data'!$H:$H,'Forecast Data'!$B:$B,$B4,'Forecast Data'!$C:$C,AO$6) -> 0.38556915 | AP4: =(AC4-SUMIFS('Forecast Data'!$H:$H,'Forecast Data'!$B:$B,$B4,'Forecast Data'!$C:$C,AP$6))/SUMIFS('Forecast Data'!$H:$H,'Forecast Data'!$B:$B,$B4,'Forecast Data'!$C:$C,AP$6) -> 0.43020933 | AQ4: =(AD4-SUMIFS('Forecast Data'!$H:$H,'Forecast Data'!$B:$B,$B4,'Forecast Data'!$C:$C,AQ$6))/SUMIFS('Forecast Data'!$H:$H,'Forecast Data'!$B:$B,$B4,'Forecast Data'!$C:$C,AQ$6) -> 0.38755311 | ... AU4: =(AH4-SUMIFS('Forecast Data'!$H:$H,'Forecast Data'!$B:$B,$B4,'Forecast Data'!$C:$C,AU$6))/SUMIFS('Forecast Data'!$H:$H,'Forecast Data'!$B:$B,$B4,'Forecast Data'!$C:$C,AU$6) -> 0.38976388 | AW4: =SUM(AW8:AW537) -> 1431629 | AX4: =SUM(AX8:AX537) -> 1497491 | AY4: =SUM(AY8:AY537) -> 1488441 | AZ4: =SUM(AZ8:AZ537) -> 1522161 | BA4: =SUM(BA8:BA537) -> 1498053 | BB4: =SUM(BB8:BB537) -> 1519932 | BC4: =SUM(BC8:BC537) -> 1444287 | BD4: =SUM(BD8:BD537) -> 1425161 | ... BH4: =SUM(BH8:BH537) -> 1434476 | BJ4: =IFERROR((SUMIFS('OP Units'!E:E,'OP Units'!$A:$A,$B4)-SUMIFS('Forecast Data'!$H:$H,'Forecast Data'!$C:$C,BJ$6,'Forecast Data'!$B:$B,$B4))/SUMIFS('Forecast Data'!$H:$H,'Forecast Data'!$C:$C,BJ$6,'Forecast Data'!$B:$B,$B4),"") -> 0.19207689 | BK4: =IFERROR((SUMIFS('OP Units'!F:F,'OP Units'!$A:$A,$B4)-SUMIFS('Forecast Data'!$H:$H,'Forecast Data'!$C:$C,BK$6,'Forecast Data'!$B:$B,$B4))/SUMIFS('Forecast Data'!$H:$H,'Forecast Data'!$C:$C,BK$6,'Forecast Data'!$B:$B,$B4),"") -> 0.24251631 | BL4: =IFERROR((SUMIFS('OP Units'!G:G,'OP Units'!$A:$A,$B4)-SUMIFS('Forecast Data'!$H:$H,'Forecast Data'!$C:$C,BL$6,'Forecast Data'!$B:$B,$B4))/SUMIFS('Forecast Data'!$H:$H,'Forecast Data'!$C:$C,BL$6,'Forecast Data'!$B:$B,$B4),"") -> 0.26559042 | BM4: =IFERROR((SUMIFS('OP Units'!H:H,'OP Units'!$A:$A,$B4)-SUMIFS('Forecast Data'!$H:$H,'Forecast Data'!$C:$C,BM$6,'Forecast Data'!$B:$B,$B4))/SUMIFS('Forecast Data'!$H:$H,'Forecast Data'!$C:$C,BM$6,'Forecast Data'!$B:$B,$B4),"") -> 0.25349565 | BN4: =IFERROR((SUMIFS('OP Units'!I:I,'OP Units'!$A:$A,$B4)-SUMIFS('Forecast Data'!$H:$H,'Forecast Data'!$C:$C,BN$6,'Forecast Data'!$B:$B,$B4))/SUMIFS('Forecast Data'!$H:$H,'Forecast Data'!$C:$C,BN$6,'Forecast Data'!$B:$B,$B4),"") -> 0.22025035 | BO4: =IFERROR((SUMIFS('OP Units'!J:J,'OP Units'!$A:$A,$B4)-SUMIFS('Forecast Data'!$H:$H,'Forecast Data'!$C:$C,BO$6,'Forecast Data'!$B:$B,$B4))/SUMIFS('Forecast Data'!$H:$H,'Forecast Data'!$C:$C,BO$6,'Forecast Data'!$B:$B,$B4),"") -> 0.19838926 | BP4: =IFERROR((SUMIFS('OP Units'!K:K,'OP Units'!$A:$A,$B4)-SUMIFS('Forecast Data'!$H:$H,'Forecast Data'!$C:$C,BP$6,'Forecast Data'!$B:$B,$B4))/SUMIFS('Forecast Data'!$H:$H,'Forecast Data'!$C:$C,BP$6,'Forecast Data'!$B:$B,$B4),"") -> 0.16759256 | BQ4: =IFERROR((SUMIFS('OP Units'!L:L,'OP Units'!$A:$A,$B4)-SUMIFS('Forecast Data'!$H:$H,'Forecast Data'!$C:$C,BQ$6,'Forecast Data'!$B:$B,$B4))/SUMIFS('Forecast Data'!$H:$H,'Forecast Data'!$C:$C,BQ$6,'Forecast Data'!$B:$B,$B4),"") -> 0.13849992 | BR4: =IFERROR((SUMIFS('OP Units'!M:M,'OP Units'!$A:$A,$B4)-SUMIFS('Forecast Data'!$H:$H,'Forecast Data'!$C:$C,BR$6,'Forecast Data'!$B:$B,$B4))/SUMIFS('Forecast Data'!$H:$H,'Forecast Data'!$C:$C,BR$6,'Forecast Data'!$B:$B,$B4),"") -> 0.13941445 | BS4: =IFERROR((SUMIFS('OP Units'!N:N,'OP Units'!$A:$A,$B4)-SUMIFS('Forecast Data'!$H:$H,'Forecast Data'!$C:$C,BS$6,'Forecast Data'!$B:$B,$B4))/SUMIFS('Forecast Data'!$H:$H,'Forecast Data'!$C:$C,BS$6,'Forecast Data'!$B:$B,$B4),"") -> 0.17100688 | BT4: =IFERROR((SUMIFS('OP Units'!O:O,'OP Units'!$A:$A,$B4)-SUMIFS('Forecast Data'!$H:$H,'Forecast Data'!$C:$C,BT$6,'Forecast Data'!$B:$B,$B4))/SUMIFS('Forecast Data'!$H:$H,'Forecast Data'!$C:$C,BT$6,'Forecast Data'!$B:$B,$B4),"") -> 0.17591798 | BU4: =IFERROR((SUMIFS('OP Units'!P:P,'OP Units'!$A:$A,$B4)-SUMIFS('Forecast Data'!$H:$H,'Forecast Data'!$C:$C,BU$6,'Forecast Data'!$B:$B,$B4))/SUMIFS('Forecast Data'!$H:$H,'Forecast Data'!$C:$C,BU$6,'Forecast Data'!$B:$B,$B4),"") -> 0.13731486 | BW4: =SUM(BW8:BW537) -> 1217238.4 | BX4: =IFERROR((SUM(W4:AD4)-(SUMIFS('Forecast Data'!H:H,'Forecast Data'!B:B,B4,'Forecast Data'!C:C,BJ$6)+SUMIFS('Forecast Data'!H:H,'Forecast Data'!B:B,B4,'Forecast Data'!C:C,BK$6)+SUMIFS('Forecast Data'!H:H,'Forecast Data'!B:B,B4,'Forecast Data'!C:C,BL$6)+SUMIFS('Forecast Data'!H:H,'Forecast Data'!B:B,B4,'Forecast Data'!C:C,BM$6)+SUMIFS('Forecast Data'!H:H,'Forecast Data'!B:B,B4,'Forecast Data'!C:C,BN$6)+SUMIFS('Forecast Data'!H:H,'Forecast Data'!B:B,B4,'Forecast Data'!C:C,BO$6)+SUMIFS('Forecast Data'!H:H,'Forecast Data'!B:B,B4,'Forecast Data'!C:C,BP$6)+SUMIFS('Forecast Data'!H:H,'Forecast Data'!B:B,B4,'Forecast Data'!C:C,BQ$6)))/(SUMIFS('Forecast Data'!H:H,'Forecast Data'!B:B,B4,'Forecast Data'!C:C,BJ$6)+SUMIFS('Forecast Data'!H:H,'Forecast Data'!B:B,B4,'Forecast Data'!C:C,BK$6)+SUMIFS('Forecast Data'!H:H,'Forecast Data'!B:B,B4,'Forecast Data'!C:C,BL$6)+SUMIFS('Forecast Data'!H:H,'Forecast Data'!B:B,B4,'Forecast Data'!C:C,BM$6)+SUMIFS('Forecast Data'!H:H,'Forecast Data'!B:B,B4,'Forecast Data'!C:C,BN$6)+SUMIFS('Forecast Data'!H:H,'Forecast Data'!B:B,B4,'Forecast Data'!C:C,BO$6)+SUMIFS('Forecast Data'!H:H,'Forecast Data'!B:B,B4,'Forecast Data'!C:C,BP$6)+SUMIFS('Forecast Data'!H:H,'Forecast Data'!B:B,B4,'Forecast Data'!C:C,BQ$6)),"") -> 0.42168532 | BY4: =SUM(BY8:BY508) -> 0.32845347 | BZ4: =SUM(BZ8:BZ508) -> 0.41139785 | CA4: =SUM(CA8:CA537) -> -2.1614174 | CD4: =SUM(CD8:CD537) -> 1193860.8 | CE4: =IFERROR((SUM(W4:Z4)-(SUMIFS('Forecast Data'!H:H,'Forecast Data'!B:B,B4,'Forecast Data'!C:C,BJ$6)+SUMIFS('Forecast Data'!H:H,'Forecast Data'!B:B,B4,'Forecast Data'!C:C,BK$6)+SUMIFS('Forecast Data'!H:H,'Forecast Data'!B:B,B4,'Forecast Data'!C:C,BL$6)+SUMIFS('Forecast Data'!H:H,'Forecast Data'!B:B,B4,'Forecast Data'!C:C,BM$6)))/(SUMIFS('Forecast Data'!H:H,'Forecast Data'!B:B,B4,'Forecast Data'!C:C,BJ$6)+SUMIFS('Forecast Data'!H:H,'Forecast Data'!B:B,B4,'Forecast Data'!C:C,BK$6)+SUMIFS('Forecast Data'!H:H,'Forecast Data'!B:B,B4,'Forecast Data'!C:C,BL$6)+SUMIFS('Forecast Data'!H:H,'Forecast Data'!B:B,B4,'Forecast Data'!C:C,BM$6)),"") -> 0.44180583 | CF4: =SUM(CF8:CF508) -> 0.32845347 | CG4: =SUM(CG8:CG508) -> 0.4192761 | CH4: =SUM(CH8:CH537) -> -4.1734686
W6: 46103 | X6: =W6+7 -> 46110 | Y6: =X6+7 -> 46117 | Z6: =Y6+7 -> 46124 | AA6: =Z6+7 -> 46131 | AB6: =AA6+7 -> 46138 | AC6: =AB6+7 -> 46145 | AD6: =AC6+7 -> 46152 | AE6: =AD6+7 -> 46159 | ... AH6: =AG6+7 -> 46180 | AJ6: =W6 -> 46103 | AK6: =X6 -> 46110 | AL6: =Y6 -> 46117 | AM6: =Z6 -> 46124 | AN6: =AA6 -> 46131 | AO6: =AB6 -> 46138 | AP6: =AC6 -> 46145 | AQ6: =AD6 -> 46152 | ... AU6: =AH6 -> 46180 | AW6: =AJ6 -> 46103 | AX6: =AK6 -> 46110 | AY6: =AL6 -> 46117 | AZ6: =AM6 -> 46124 | BA6: =AN6 -> 46131 | BB6: =AO6 -> 46138 | BC6: =AP6 -> 46145 | BD6: =AQ6 -> 46152 | ... BH6: =AU6 -> 46180 | BJ6: =AW6 -> 46103 | BK6: =AX6 -> 46110 | BL6: =AY6 -> 46117 | BM6: =AZ6 -> 46124 | BN6: =BA6 -> 46131 | BO6: =BB6 -> 46138 | BP6: =BC6 -> 46145 | BQ6: =BD6 -> 46152 | ... BU6: =BH6 -> 46180
E7: LY | F7: LW-5 | G7: LW-4 | H7: LW-3 | I7: LW-2 | J7: LW-1 | K7: LW | L7: L6W RR | M7: L6W YoY | O7: IM | P7: IM | R7: IM | S7: IM | T7: AE | U7: AE | W7: CW+1 | X7: CW+2 | Y7: CW+3 | Z7: CW+4 | AA7: CW+5 | AB7: CW+6 | AC7: CW+7 | AD7: CW+8 | AE7: CW+9 | AF7: CW+10 | AG7: CW+11 | AH7: CW+12 | AJ7: CW+1 | AK7: CW+2 | AL7: CW+3 | AM7: CW+4 | AN7: CW+5 | AO7: CW+6 | AP7: CW+7 | AQ7: CW+8 | AR7: CW+9 | AS7: CW+10 | AT7: CW+11 | AU7: CW+12 | AW7: CW+1 | AX7: CW+2 | AY7: CW+3 | AZ7: CW+4 | BA7: CW+5 | BB7: CW+6 | BC7: CW+7 | BD7: CW+8 | BE7: CW+9 | BF7: CW+10 | BG7: CW+11 | BH7: CW+12 | BJ7: CW+1 | BK7: CW+2 | BL7: CW+3 | BM7: CW+4 | BN7: CW+5 | BO7: CW+6 | BP7: CW+7 | BQ7: CW+8 | BR7: CW+9 | BS7: CW+10 | BT7: CW+11 | BU7: CW+12
B8: =D8 -> Thorne Research | D8: Thorne Research | E8: =SUMIFS('Fin Data'!F:F,'Fin Data'!A:A,D8) -> 180195 | F8: =SUMIFS('Fin Data with 6 week hist'!I:I,'Fin Data with 6 week hist'!$A:$A,$D8) -> 285756 | G8: =SUMIFS('Fin Data with 6 week hist'!J:J,'Fin Data with 6 week hist'!$A:$A,$D8) -> 281931 | H8: =SUMIFS('Fin Data with 6 week hist'!K:K,'Fin Data with 6 week hist'!$A:$A,$D8)+SUMIFS('Unit Cancellations'!D:D,'Unit Cancellations'!$B:$B,$D8) -> 280344 | I8: =SUMIFS('Fin Data with 6 week hist'!L:L,'Fin Data with 6 week hist'!$A:$A,$D8)+SUMIFS('Unit Cancellations'!E:E,'Unit Cancellations'!$B:$B,$D8) -> 283674 | J8: =SUMIFS('Fin Data with 6 week hist'!M:M,'Fin Data with 6 week hist'!$A:$A,$D8)+SUMIFS('Unit Cancellations'!F:F,'Unit Cancellations'!$B:$B,$D8) -> 287398 | K8: =SUMIFS('Fin Data with 6 week hist'!N:N,'Fin Data with 6 week hist'!$A:$A,$D8)+SUMIFS('Unit Cancellations'!G:G,'Unit Cancellations'!$B:$B,$D8) -> 295501 | L8: =SUMIFS('Fin Data'!AN:AN,'Fin Data'!A:A,D8) -> 285767.33 | M8: =IFERROR(SUMIFS('Fin Data'!AO:AO,'Fin Data'!A:A,D8),"") -> 0.58587826 | O8: =AVERAGE(W8:Z8) -> 290945.75 | P8: =CE8 -> 0.61210216 | R8: =AVERAGE(W8:AD8) -> 292095.25 | S8: =BX8 -> 0.57114157 | T8: =AVERAGE(AW8:BD8) -> 235822.75 | U8: =#REF! -> #REF! | W8: =SUMIFS('Forecast Data'!$D:$D,'Forecast Data'!$C:$C,W$6,'Forecast Data'!$B:$B,$D8) -> 289133 | X8: =SUMIFS('Forecast Data'!$D:$D,'Forecast Data'!$C:$C,X$6,'Forecast Data'!$B:$B,$D8) -> 289774 | Y8: =SUMIFS('Forecast Data'!$D:$D,'Forecast Data'!$C:$C,Y$6,'Forecast Data'!$B:$B,$D8) -> 292319 | Z8: =SUMIFS('Forecast Data'!$D:$D,'Forecast Data'!$C:$C,Z$6,'Forecast Data'!$B:$B,$D8) -> 292557 | AA8: =SUMIFS('Forecast Data'!$D:$D,'Forecast Data'!$C:$C,AA$6,'Forecast Data'!$B:$B,$D8) -> 292472 | AB8: =SUMIFS('Forecast Data'!$D:$D,'Forecast Data'!$C:$C,AB$6,'Forecast Data'!$B:$B,$D8) -> 291768 | AC8: =SUMIFS('Forecast Data'!$D:$D,'Forecast Data'!$C:$C,AC$6,'Forecast Data'!$B:$B,$D8) -> 294096 | AD8: =SUMIFS('Forecast Data'!$D:$D,'Forecast Data'!$C:$C,AD$6,'Forecast Data'!$B:$B,$D8) -> 294643 | ... AH8: =SUMIFS('Forecast Data'!$D:$D,'Forecast Data'!$C:$C,AH$6,'Forecast Data'!$B:$B,$D8) -> 295151 | AJ8: =IF(SUMIFS('Forecast Data'!$E:$E,'Forecast Data'!$C:$C,AJ$6,'Forecast Data'!$B:$B,$D8)=0,"",SUMIFS('Forecast Data'!$E:$E,'Forecast Data'!$C:$C,AJ$6,'Forecast Data'!$B:$B,$D8)) -> 0.62 | AK8: =IF(SUMIFS('Forecast Data'!$E:$E,'Forecast Data'!$C:$C,AK$6,'Forecast Data'!$B:$B,$D8)=0,"",SUMIFS('Forecast Data'!$E:$E,'Forecast Data'!$C:$C,AK$6,'Forecast Data'!$B:$B,$D8)) -> 0.61 | AL8: =IF(SUMIFS('Forecast Data'!$E:$E,'Forecast Data'!$C:$C,AL$6,'Forecast Data'!$B:$B,$D8)=0,"",SUMIFS('Forecast Data'!$E:$E,'Forecast Data'!$C:$C,AL$6,'Forecast Data'!$B:$B,$D8)) -> 0.66 | AM8: =IF(SUMIFS('Forecast Data'!$E:$E,'Forecast Data'!$C:$C,AM$6,'Forecast Data'!$B:$B,$D8)=0,"",SUMIFS('Forecast Data'!$E:$E,'Forecast Data'!$C:$C,AM$6,'Forecast Data'!$B:$B,$D8)) -> 0.57 | AN8: =IF(SUMIFS('Forecast Data'!$E:$E,'Forecast Data'!$C:$C,AN$6,'Forecast Data'!$B:$B,$D8)=0,"",SUMIFS('Forecast Data'!$E:$E,'Forecast Data'!$C:$C,AN$6,'Forecast Data'!$B:$B,$D8)) -> 0.52 | AO8: =IF(SUMIFS('Forecast Data'!$E:$E,'Forecast Data'!$C:$C,AO$6,'Forecast Data'!$B:$B,$D8)=0,"",SUMIFS('Forecast Data'!$E:$E,'Forecast Data'!$C:$C,AO$6,'Forecast Data'!$B:$B,$D8)) -> 0.49 | AP8: =IF(SUMIFS('Forecast Data'!$E:$E,'Forecast Data'!$C:$C,AP$6,'Forecast Data'!$B:$B,$D8)=0,"",SUMIFS('Forecast Data'!$E:$E,'Forecast Data'!$C:$C,AP$6,'Forecast Data'!$B:$B,$D8)) -> 0.59 | AQ8: =IF(SUMIFS('Forecast Data'!$E:$E,'Forecast Data'!$C:$C,AQ$6,'Forecast Data'!$B:$B,$D8)=0,"",SUMIFS('Forecast Data'!$E:$E,'Forecast Data'!$C:$C,AQ$6,'Forecast Data'!$B:$B,$D8)) -> 0.53 | ... AU8: =IF(SUMIFS('Forecast Data'!$E:$E,'Forecast Data'!$C:$C,AU$6,'Forecast Data'!$B:$B,$D8)=0,"",SUMIFS('Forecast Data'!$E:$E,'Forecast Data'!$C:$C,AU$6,'Forecast Data'!$B:$B,$D8)) -> 0.5 | AW8: =SUMIFS('OP Units'!E:E,'OP Units'!$A:$A,$D8) -> 234450 | AX8: =SUMIFS('OP Units'!F:F,'OP Units'!$A:$A,$D8) -> 246136 | AY8: =SUMIFS('OP Units'!G:G,'OP Units'!$A:$A,$D8) -> 234443 | AZ8: =SUMIFS('OP Units'!H:H,'OP Units'!$A:$A,$D8) -> 245277 | BA8: =SUMIFS('OP Units'!I:I,'OP Units'!$A:$A,$D8) -> 233353 | BB8: =SUMIFS('OP Units'!J:J,'OP Units'!$A:$A,$D8) -> 225162 | BC8: =SUMIFS('OP Units'!K:K,'OP Units'!$A:$A,$D8) -> 234102 | BD8: =SUMIFS('OP Units'!L:L,'OP Units'!$A:$A,$D8) -> 233659 | BE8: =SUMIFS('OP Units'!M:M,'OP Units'!$A:$A,$D8) -> 233749 | BF8: =SUMIFS('OP Units'!N:N,'OP Units'!$A:$A,$D8) -> 235561 | BG8: =SUMIFS('OP Units'!O:O,'OP Units'!$A:$A,$D8) -> 238972 | BH8: =SUMIFS('OP Units'!P:P,'OP Units'!$A:$A,$D8) -> 235680 | BJ8: =IFERROR((SUMIFS('OP Units'!E:E,'OP Units'!$A:$A,$D8)-SUMIFS('Forecast Data'!$H:$H,'Forecast Data'!$C:$C,BJ$6,'Forecast Data'!$B:$B,$D8))/SUMIFS('Forecast Data'!$H:$H,'Forecast Data'!$C:$C,BJ$6,'Forecast Data'!$B:$B,$D8),"") -> 0.31006197 | BK8: =IFERROR((SUMIFS('OP Units'!F:F,'OP Units'!$A:$A,$D8)-SUMIFS('Forecast Data'!$H:$H,'Forecast Data'!$C:$C,BK$6,'Forecast Data'!$B:$B,$D8))/SUMIFS('Forecast Data'!$H:$H,'Forecast Data'!$C:$C,BK$6,'Forecast Data'!$B:$B,$D8),"") -> 0.36764256 | BL8: =IFERROR((SUMIFS('OP Units'!G:G,'OP Units'!$A:$A,$D8)-SUMIFS('Forecast Data'!$H:$H,'Forecast Data'!$C:$C,BL$6,'Forecast Data'!$B:$B,$D8))/SUMIFS('Forecast Data'!$H:$H,'Forecast Data'!$C:$C,BL$6,'Forecast Data'!$B:$B,$D8),"") -> 0.33120025 | BM8: =IFERROR((SUMIFS('OP Units'!H:H,'OP Units'!$A:$A,$D8)-SUMIFS('Forecast Data'!$H:$H,'Forecast Data'!$C:$C,BM$6,'Forecast Data'!$B:$B,$D8))/SUMIFS('Forecast Data'!$H:$H,'Forecast Data'!$C:$C,BM$6,'Forecast Data'!$B:$B,$D8),"") -> 0.31263847 | BN8: =IFERROR((SUMIFS('OP Units'!I:I,'OP Units'!$A:$A,$D8)-SUMIFS('Forecast Data'!$H:$H,'Forecast Data'!$C:$C,BN$6,'Forecast Data'!$B:$B,$D8))/SUMIFS('Forecast Data'!$H:$H,'Forecast Data'!$C:$C,BN$6,'Forecast Data'!$B:$B,$D8),"") -> 0.21163172 | BO8: =IFERROR((SUMIFS('OP Units'!J:J,'OP Units'!$A:$A,$D8)-SUMIFS('Forecast Data'!$H:$H,'Forecast Data'!$C:$C,BO$6,'Forecast Data'!$B:$B,$D8))/SUMIFS('Forecast Data'!$H:$H,'Forecast Data'!$C:$C,BO$6,'Forecast Data'!$B:$B,$D8),"") -> 0.14806524 | BP8: =IFERROR((SUMIFS('OP Units'!K:K,'OP Units'!$A:$A,$D8)-SUMIFS('Forecast Data'!$H:$H,'Forecast Data'!$C:$C,BP$6,'Forecast Data'!$B:$B,$D8))/SUMIFS('Forecast Data'!$H:$H,'Forecast Data'!$C:$C,BP$6,'Forecast Data'!$B:$B,$D8),"") -> 0.26847427 | BQ8: =IFERROR((SUMIFS('OP Units'!L:L,'OP Units'!$A:$A,$D8)-SUMIFS('Forecast Data'!$H:$H,'Forecast Data'!$C:$C,BQ$6,'Forecast Data'!$B:$B,$D8))/SUMIFS('Forecast Data'!$H:$H,'Forecast Data'!$C:$C,BQ$6,'Forecast Data'!$B:$B,$D8),"") -> 0.21616951 | BR8: =IFERROR((SUMIFS('OP Units'!M:M,'OP Units'!$A:$A,$D8)-SUMIFS('Forecast Data'!$H:$H,'Forecast Data'!$C:$C,BR$6,'Forecast Data'!$B:$B,$D8))/SUMIFS('Forecast Data'!$H:$H,'Forecast Data'!$C:$C,BR$6,'Forecast Data'!$B:$B,$D8),"") -> 0.18951997 | BS8: =IFERROR((SUMIFS('OP Units'!N:N,'OP Units'!$A:$A,$D8)-SUMIFS('Forecast Data'!$H:$H,'Forecast Data'!$C:$C,BS$6,'Forecast Data'!$B:$B,$D8))/SUMIFS('Forecast Data'!$H:$H,'Forecast Data'!$C:$C,BS$6,'Forecast Data'!$B:$B,$D8),"") -> 0.18097 | BT8: =IFERROR((SUMIFS('OP Units'!O:O,'OP Units'!$A:$A,$D8)-SUMIFS('Forecast Data'!$H:$H,'Forecast Data'!$C:$C,BT$6,'Forecast Data'!$B:$B,$D8))/SUMIFS('Forecast Data'!$H:$H,'Forecast Data'!$C:$C,BT$6,'Forecast Data'!$B:$B,$D8),"") -> 0.21982992 | BU8: =IFERROR((SUMIFS('OP Units'!P:P,'OP Units'!$A:$A,$D8)-SUMIFS('Forecast Data'!$H:$H,'Forecast Data'!$C:$C,BU$6,'Forecast Data'!$B:$B,$D8))/SUMIFS('Forecast Data'!$H:$H,'Forecast Data'!$C:$C,BU$6,'Forecast Data'!$B:$B,$D8),"") -> 0.19398146 | BW8: =(SUMIFS('Forecast Data'!H:H,'Forecast Data'!B:B,D8,'Forecast Data'!C:C,BK$6)+SUMIFS('Forecast Data'!H:H,'Forecast Data'!B:B,D8,'Forecast Data'!C:C,BL$6)+SUMIFS('Forecast Data'!H:H,'Forecast Data'!B:B,D8,'Forecast Data'!C:C,BM$6)+SUMIFS('Forecast Data'!H:H,'Forecast Data'!B:B,D8,'Forecast Data'!C:C,BN$6)+SUMIFS('Forecast Data'!H:H,'Forecast Data'!B:B,D8,'Forecast Data'!C:C,BO$6)+SUMIFS('Forecast Data'!H:H,'Forecast Data'!B:B,D8,'Forecast Data'!C:C,BP$6)+SUMIFS('Forecast Data'!H:H,'Forecast Data'!B:B,D8,'Forecast Data'!C:C,BQ$6)+SUMIFS('Forecast Data'!H:H,'Forecast Data'!B:B,D8,'Forecast Data'!C:C,BJ$6))/8 -> 185912.75 | BX8: =IFERROR((SUM(W8:AD8)-(SUMIFS('Forecast Data'!H:H,'Forecast Data'!B:B,B8,'Forecast Data'!C:C,BJ$6)+SUMIFS('Forecast Data'!H:H,'Forecast Data'!B:B,B8,'Forecast Data'!C:C,BK$6)+SUMIFS('Forecast Data'!H:H,'Forecast Data'!B:B,B8,'Forecast Data'!C:C,BL$6)+SUMIFS('Forecast Data'!H:H,'Forecast Data'!B:B,B8,'Forecast Data'!C:C,BM$6)+SUMIFS('Forecast Data'!H:H,'Forecast Data'!B:B,B8,'Forecast Data'!C:C,BN$6)+SUMIFS('Forecast Data'!H:H,'Forecast Data'!B:B,B8,'Forecast Data'!C:C,BO$6)+SUMIFS('Forecast Data'!H:H,'Forecast Data'!B:B,B8,'Forecast Data'!C:C,BP$6)+SUMIFS('Forecast Data'!H:H,'Forecast Data'!B:B,B8,'Forecast Data'!C:C,BQ$6)))/(SUMIFS('Forecast Data'!H:H,'Forecast Data'!B:B,B8,'Forecast Data'!C:C,BJ$6)+SUMIFS('Forecast Data'!H:H,'Forecast Data'!B:B,B8,'Forecast Data'!C:C,BK$6)+SUMIFS('Forecast Data'!H:H,'Forecast Data'!B:B,B8,'Forecast Data'!C:C,BL$6)+SUMIFS('Forecast Data'!H:H,'Forecast Data'!B:B,B8,'Forecast Data'!C:C,BM$6)+SUMIFS('Forecast Data'!H:H,'Forecast Data'!B:B,B8,'Forecast Data'!C:C,BN$6)+SUMIFS('Forecast Data'!H:H,'Forecast Data'!B:B,B8,'Forecast Data'!C:C,BO$6)+SUMIFS('Forecast Data'!H:H,'Forecast Data'!B:B,B8,'Forecast Data'!C:C,BP$6)+SUMIFS('Forecast Data'!H:H,'Forecast Data'!B:B,B8,'Forecast Data'!C:C,BQ$6)),"") -> 0.57114157 | BY8: =((L8-E8)/($L$4-$E$4))*$M$4 -> 0.090279292 | BZ8: =((AVERAGE(W8:AD8)-BW8)/(AVERAGE($W$4:$AD$4)-$BW$4))*$BX$4 -> 0.087313766 | CA8: =(BY8-BZ8)*100 -> 0.29655259 | CB8: =ABS(CA8)/100 -> 0.0029655259 | CD8: =(SUMIFS('Forecast Data'!H:H,'Forecast Data'!B:B,D8,'Forecast Data'!C:C,BK$6)+SUMIFS('Forecast Data'!H:H,'Forecast Data'!B:B,D8,'Forecast Data'!C:C,BL$6)+SUMIFS('Forecast Data'!H:H,'Forecast Data'!B:B,D8,'Forecast Data'!C:C,BM$6)+SUMIFS('Forecast Data'!H:H,'Forecast Data'!B:B,D8,'Forecast Data'!C:C,BJ$6))/4 -> 180476 | CE8: =IFERROR((SUM(W8:Z8)-(SUMIFS('Forecast Data'!H:H,'Forecast Data'!B:B,D8,'Forecast Data'!C:C,BJ$6)+SUMIFS('Forecast Data'!H:H,'Forecast Data'!B:B,D8,'Forecast Data'!C:C,BK$6)+SUMIFS('Forecast Data'!H:H,'Forecast Data'!B:B,D8,'Forecast Data'!C:C,BL$6)+SUMIFS('Forecast Data'!H:H,'Forecast Data'!B:B,D8,'Forecast Data'!C:C,BM$6)))/(SUMIFS('Forecast Data'!H:H,'Forecast Data'!B:B,D8,'Forecast Data'!C:C,BJ$6)+SUMIFS('Forecast Data'!H:H,'Forecast Data'!B:B,D8,'Forecast Data'!C:C,BK$6)+SUMIFS('Forecast Data'!H:H,'Forecast Data'!B:B,D8,'Forecast Data'!C:C,BL$6)+SUMIFS('Forecast Data'!H:H,'Forecast Data'!B:B,D8,'Forecast Data'!C:C,BM$6)),"") -> 0.61210216 | CF8: =(($L8-$E8)/($L$4-$E$4))*$M$4 -> 0.090279292 | CG8: =((AVERAGE(W8:Z8)-CD8)/(AVERAGE($W$4:$Z$4)-$CD$4))*$CE$4 -> 0.092616268 | CH8: =(CF8-CG8)*100 -> -0.2336976
B9: =D9 -> Gaia Herbs | D9: Gaia Herbs | E9: =SUMIFS('Fin Data'!F:F,'Fin Data'!A:A,D9) -> 24696 | F9: =SUMIFS('Fin Data with 6 week hist'!I:I,'Fin Data with 6 week hist'!$A:$A,$D9) -> 26075 | G9: =SUMIFS('Fin Data with 6 week hist'!J:J,'Fin Data with 6 week hist'!$A:$A,$D9) -> 24784 | H9: =SUMIFS('Fin Data with 6 week hist'!K:K,'Fin Data with 6 week hist'!$A:$A,$D9)+SUMIFS('Unit Cancellations'!D:D,'Unit Cancellations'!$B:$B,$D9) -> 23480 | I9: =SUMIFS('Fin Data with 6 week hist'!L:L,'Fin Data with 6 week hist'!$A:$A,$D9)+SUMIFS('Unit Cancellations'!E:E,'Unit Cancellations'!$B:$B,$D9) -> 23101 | J9: =SUMIFS('Fin Data with 6 week hist'!M:M,'Fin Data with 6 week hist'!$A:$A,$D9)+SUMIFS('Unit Cancellations'!F:F,'Unit Cancellations'!$B:$B,$D9) -> 23477 | K9: =SUMIFS('Fin Data with 6 week hist'!N:N,'Fin Data with 6 week hist'!$A:$A,$D9)+SUMIFS('Unit Cancellations'!G:G,'Unit Cancellations'!$B:$B,$D9) -> 24175 | L9: =SUMIFS('Fin Data'!AN:AN,'Fin Data'!A:A,D9) -> 24181.833 | M9: =IFERROR(SUMIFS('Fin Data'!AO:AO,'Fin Data'!A:A,D9),"") -> -0.020819836 | O9: =AVERAGE(W9:Z9) -> 27354.25 | P9: =CE9 -> 0.27171399 | R9: =AVERAGE(W9:AD9) -> 27313.625 | S9: =BX9 -> 0.28465939 | T9: =AVERAGE(AW9:BD9) -> 26771.875 | U9: =#REF! -> #REF! | W9: =SUMIFS('Forecast Data'!$D:$D,'Forecast Data'!$C:$C,W$6,'Forecast Data'!$B:$B,$D9) -> 27328 | X9: =SUMIFS('Forecast Data'!$D:$D,'Forecast Data'!$C:$C,X$6,'Forecast Data'!$B:$B,$D9) -> 27289 | Y9: =SUMIFS('Forecast Data'!$D:$D,'Forecast Data'!$C:$C,Y$6,'Forecast Data'!$B:$B,$D9) -> 27381 | Z9: =SUMIFS('Forecast Data'!$D:$D,'Forecast Data'!$C:$C,Z$6,'Forecast Data'!$B:$B,$D9) -> 27419 | AA9: =SUMIFS('Forecast Data'!$D:$D,'Forecast Data'!$C:$C,AA$6,'Forecast Data'!$B:$B,$D9) -> 27435 | AB9: =SUMIFS('Forecast Data'!$D:$D,'Forecast Data'!$C:$C,AB$6,'Forecast Data'!$B:$B,$D9) -> 27472 | AC9: =SUMIFS('Forecast Data'!$D:$D,'Forecast Data'!$C:$C,AC$6,'Forecast Data'!$B:$B,$D9) -> 27126 | AD9: =SUMIFS('Forecast Data'!$D:$D,'Forecast Data'!$C:$C,AD$6,'Forecast Data'!$B:$B,$D9) -> 27059 | ... AH9: =SUMIFS('Forecast Data'!$D:$D,'Forecast Data'!$C:$C,AH$6,'Forecast Data'!$B:$B,$D9) -> 27335 | AJ9: =IF(SUMIFS('Forecast Data'!$E:$E,'Forecast Data'!$C:$C,AJ$6,'Forecast Data'!$B:$B,$D9)=0,"",SUMIFS('Forecast Data'!$E:$E,'Forecast Data'!$C:$C,AJ$6,'Forecast Data'!$B:$B,$D9)) -> 0.25 | AK9: =IF(SUMIFS('Forecast Data'!$E:$E,'Forecast Data'!$C:$C,AK$6,'Forecast Data'!$B:$B,$D9)=0,"",SUMIFS('Forecast Data'!$E:$E,'Forecast Data'!$C:$C,AK$6,'Forecast Data'!$B:$B,$D9)) -> 0.26 | AL9: =IF(SUMIFS('Forecast Data'!$E:$E,'Forecast Data'!$C:$C,AL$6,'Forecast Data'!$B:$B,$D9)=0,"",SUMIFS('Forecast Data'!$E:$E,'Forecast Data'!$C:$C,AL$6,'Forecast Data'!$B:$B,$D9)) -> 0.3 | AM9: =IF(SUMIFS('Forecast Data'!$E:$E,'Forecast Data'!$C:$C,AM$6,'Forecast Data'!$B:$B,$D9)=0,"",SUMIFS('Forecast Data'!$E:$E,'Forecast Data'!$C:$C,AM$6,'Forecast Data'!$B:$B,$D9)) -> 0.28 | AN9: =IF(SUMIFS('Forecast Data'!$E:$E,'Forecast Data'!$C:$C,AN$6,'Forecast Data'!$B:$B,$D9)=0,"",SUMIFS('Forecast Data'!$E:$E,'Forecast Data'!$C:$C,AN$6,'Forecast Data'!$B:$B,$D9)) -> 0.29 | AO9: =IF(SUMIFS('Forecast Data'!$E:$E,'Forecast Data'!$C:$C,AO$6,'Forecast Data'!$B:$B,$D9)=0,"",SUMIFS('Forecast Data'!$E:$E,'Forecast Data'!$C:$C,AO$6,'Forecast Data'!$B:$B,$D9)) -> 0.23 | AP9: =IF(SUMIFS('Forecast Data'!$E:$E,'Forecast Data'!$C:$C,AP$6,'Forecast Data'!$B:$B,$D9)=0,"",SUMIFS('Forecast Data'!$E:$E,'Forecast Data'!$C:$C,AP$6,'Forecast Data'!$B:$B,$D9)) -> 0.33 | AQ9: =IF(SUMIFS('Forecast Data'!$E:$E,'Forecast Data'!$C:$C,AQ$6,'Forecast Data'!$B:$B,$D9)=0,"",SUMIFS('Forecast Data'!$E:$E,'Forecast Data'!$C:$C,AQ$6,'Forecast Data'!$B:$B,$D9)) -> 0.35 | ... AU9: =IF(SUMIFS('Forecast Data'!$E:$E,'Forecast Data'!$C:$C,AU$6,'Forecast Data'!$B:$B,$D9)=0,"",SUMIFS('Forecast Data'!$E:$E,'Forecast Data'!$C:$C,AU$6,'Forecast Data'!$B:$B,$D9)) -> 0.49 | AW9: =SUMIFS('OP Units'!E:E,'OP Units'!$A:$A,$D9) -> 27125 | AX9: =SUMIFS('OP Units'!F:F,'OP Units'!$A:$A,$D9) -> 28282 | AY9: =SUMIFS('OP Units'!G:G,'OP Units'!$A:$A,$D9) -> 27414 | AZ9: =SUMIFS('OP Units'!H:H,'OP Units'!$A:$A,$D9) -> 28491 | BA9: =SUMIFS('OP Units'!I:I,'OP Units'!$A:$A,$D9) -> 26911 | BB9: =SUMIFS('OP Units'!J:J,'OP Units'!$A:$A,$D9) -> 24801 | BC9: =SUMIFS('OP Units'!K:K,'OP Units'!$A:$A,$D9) -> 25920 | BD9: =SUMIFS('OP Units'!L:L,'OP Units'!$A:$A,$D9) -> 25231 | BE9: =SUMIFS('OP Units'!M:M,'OP Units'!$A:$A,$D9) -> 25403 | BF9: =SUMIFS('OP Units'!N:N,'OP Units'!$A:$A,$D9) -> 23942 | BG9: =SUMIFS('OP Units'!O:O,'OP Units'!$A:$A,$D9) -> 24211 | BH9: =SUMIFS('OP Units'!P:P,'OP Units'!$A:$A,$D9) -> 24065 | BJ9: =IFERROR((SUMIFS('OP Units'!E:E,'OP Units'!$A:$A,$D9)-SUMIFS('Forecast Data'!$H:$H,'Forecast Data'!$C:$C,BJ$6,'Forecast Data'!$B:$B,$D9))/SUMIFS('Forecast Data'!$H:$H,'Forecast Data'!$C:$C,BJ$6,'Forecast Data'!$B:$B,$D9),"") -> 0.24147558 | BK9: =IFERROR((SUMIFS('OP Units'!F:F,'OP Units'!$A:$A,$D9)-SUMIFS('Forecast Data'!$H:$H,'Forecast Data'!$C:$C,BK$6,'Forecast Data'!$B:$B,$D9))/SUMIFS('Forecast Data'!$H:$H,'Forecast Data'!$C:$C,BK$6,'Forecast Data'!$B:$B,$D9),"") -> 0.30729407 | BL9: =IFERROR((SUMIFS('OP Units'!G:G,'OP Units'!$A:$A,$D9)-SUMIFS('Forecast Data'!$H:$H,'Forecast Data'!$C:$C,BL$6,'Forecast Data'!$B:$B,$D9))/SUMIFS('Forecast Data'!$H:$H,'Forecast Data'!$C:$C,BL$6,'Forecast Data'!$B:$B,$D9),"") -> 0.29733567 | BM9: =IFERROR((SUMIFS('OP Units'!H:H,'OP Units'!$A:$A,$D9)-SUMIFS('Forecast Data'!$H:$H,'Forecast Data'!$C:$C,BM$6,'Forecast Data'!$B:$B,$D9))/SUMIFS('Forecast Data'!$H:$H,'Forecast Data'!$C:$C,BM$6,'Forecast Data'!$B:$B,$D9),"") -> 0.32980163 | BN9: =IFERROR((SUMIFS('OP Units'!I:I,'OP Units'!$A:$A,$D9)-SUMIFS('Forecast Data'!$H:$H,'Forecast Data'!$C:$C,BN$6,'Forecast Data'!$B:$B,$D9))/SUMIFS('Forecast Data'!$H:$H,'Forecast Data'!$C:$C,BN$6,'Forecast Data'!$B:$B,$D9),"") -> 0.26212363 | BO9: =IFERROR((SUMIFS('OP Units'!J:J,'OP Units'!$A:$A,$D9)-SUMIFS('Forecast Data'!$H:$H,'Forecast Data'!$C:$C,BO$6,'Forecast Data'!$B:$B,$D9))/SUMIFS('Forecast Data'!$H:$H,'Forecast Data'!$C:$C,BO$6,'Forecast Data'!$B:$B,$D9),"") -> 0.11125549 | BP9: =IFERROR((SUMIFS('OP Units'!K:K,'OP Units'!$A:$A,$D9)-SUMIFS('Forecast Data'!$H:$H,'Forecast Data'!$C:$C,BP$6,'Forecast Data'!$B:$B,$D9))/SUMIFS('Forecast Data'!$H:$H,'Forecast Data'!$C:$C,BP$6,'Forecast Data'!$B:$B,$D9),"") -> 0.26903305 | BQ9: =IFERROR((SUMIFS('OP Units'!L:L,'OP Units'!$A:$A,$D9)-SUMIFS('Forecast Data'!$H:$H,'Forecast Data'!$C:$C,BQ$6,'Forecast Data'!$B:$B,$D9))/SUMIFS('Forecast Data'!$H:$H,'Forecast Data'!$C:$C,BQ$6,'Forecast Data'!$B:$B,$D9),"") -> 0.26237054 | BR9: =IFERROR((SUMIFS('OP Units'!M:M,'OP Units'!$A:$A,$D9)-SUMIFS('Forecast Data'!$H:$H,'Forecast Data'!$C:$C,BR$6,'Forecast Data'!$B:$B,$D9))/SUMIFS('Forecast Data'!$H:$H,'Forecast Data'!$C:$C,BR$6,'Forecast Data'!$B:$B,$D9),"") -> 0.24848872 | BS9: =IFERROR((SUMIFS('OP Units'!N:N,'OP Units'!$A:$A,$D9)-SUMIFS('Forecast Data'!$H:$H,'Forecast Data'!$C:$C,BS$6,'Forecast Data'!$B:$B,$D9))/SUMIFS('Forecast Data'!$H:$H,'Forecast Data'!$C:$C,BS$6,'Forecast Data'!$B:$B,$D9),"") -> 0.26865197 | BT9: =IFERROR((SUMIFS('OP Units'!O:O,'OP Units'!$A:$A,$D9)-SUMIFS('Forecast Data'!$H:$H,'Forecast Data'!$C:$C,BT$6,'Forecast Data'!$B:$B,$D9))/SUMIFS('Forecast Data'!$H:$H,'Forecast Data'!$C:$C,BT$6,'Forecast Data'!$B:$B,$D9),"") -> 0.28413069 | BU9: =IFERROR((SUMIFS('OP Units'!P:P,'OP Units'!$A:$A,$D9)-SUMIFS('Forecast Data'!$H:$H,'Forecast Data'!$C:$C,BU$6,'Forecast Data'!$B:$B,$D9))/SUMIFS('Forecast Data'!$H:$H,'Forecast Data'!$C:$C,BU$6,'Forecast Data'!$B:$B,$D9),"") -> 0.31072985 | BW9: =(SUMIFS('Forecast Data'!H:H,'Forecast Data'!B:B,D9,'Forecast Data'!C:C,BK$6)+SUMIFS('Forecast Data'!H:H,'Forecast Data'!B:B,D9,'Forecast Data'!C:C,BL$6)+SUMIFS('Forecast Data'!H:H,'Forecast Data'!B:B,D9,'Forecast Data'!C:C,BM$6)+SUMIFS('Forecast Data'!H:H,'Forecast Data'!B:B,D9,'Forecast Data'!C:C,BN$6)+SUMIFS('Forecast Data'!H:H,'Forecast Data'!B:B,D9,'Forecast Data'!C:C,BO$6)+SUMIFS('Forecast Data'!H:H,'Forecast Data'!B:B,D9,'Forecast Data'!C:C,BP$6)+SUMIFS('Forecast Data'!H:H,'Forecast Data'!B:B,D9,'Forecast Data'!C:C,BQ$6)+SUMIFS('Forecast Data'!H:H,'Forecast Data'!B:B,D9,'Forecast Data'!C:C,BJ$6))/8 -> 21261.375 | BX9: =IFERROR((SUM(W9:AD9)-(SUMIFS('Forecast Data'!H:H,'Forecast Data'!B:B,B9,'Forecast Data'!C:C,BJ$6)+SUMIFS('Forecast Data'!H:H,'Forecast Data'!B:B,B9,'Forecast Data'!C:C,BK$6)+SUMIFS('Forecast Data'!H:H,'Forecast Data'!B:B,B9,'Forecast Data'!C:C,BL$6)+SUMIFS('Forecast Data'!H:H,'Forecast Data'!B:B,B9,'Forecast Data'!C:C,BM$6)+SUMIFS('Forecast Data'!H:H,'Forecast Data'!B:B,B9,'Forecast Data'!C:C,BN$6)+SUMIFS('Forecast Data'!H:H,'Forecast Data'!B:B,B9,'Forecast Data'!C:C,BO$6)+SUMIFS('Forecast Data'!H:H,'Forecast Data'!B:B,B9,'Forecast Data'!C:C,BP$6)+SUMIFS('Forecast Data'!H:H,'Forecast Data'!B:B,B9,'Forecast Data'!C:C,BQ$6)))/(SUMIFS('Forecast Data'!H:H,'Forecast Data'!B:B,B9,'Forecast Data'!C:C,BJ$6)+SUMIFS('Forecast Data'!H:H,'Forecast Data'!B:B,B9,'Forecast Data'!C:C,BK$6)+SUMIFS('Forecast Data'!H:H,'Forecast Data'!B:B,B9,'Forecast Data'!C:C,BL$6)+SUMIFS('Forecast Data'!H:H,'Forecast Data'!B:B,B9,'Forecast Data'!C:C,BM$6)+SUMIFS('Forecast Data'!H:H,'Forecast Data'!B:B,B9,'Forecast Data'!C:C,BN$6)+SUMIFS('Forecast Data'!H:H,'Forecast Data'!B:B,B9,'Forecast Data'!C:C,BO$6)+SUMIFS('Forecast Data'!H:H,'Forecast Data'!B:B,B9,'Forecast Data'!C:C,BP$6)+SUMIFS('Forecast Data'!H:H,'Forecast Data'!B:B,B9,'Forecast Data'!C:C,BQ$6)),"") -> 0.28465939 | BY9: =((L9-E9)/($L$4-$E$4))*$M$4 -> -0.0004396853 | BZ9: =((AVERAGE(W9:AD9)-BW9)/(AVERAGE($W$4:$AD$4)-$BW$4))*$BX$4 -> 0.0049767593 | CA9: =(BY9-BZ9)*100 -> -0.54164446 | CB9: =ABS(CA9)/100 -> 0.0054164446 | CD9: =(SUMIFS('Forecast Data'!H:H,'Forecast Data'!B:B,D9,'Forecast Data'!C:C,BK$6)+SUMIFS('Forecast Data'!H:H,'Forecast Data'!B:B,D9,'Forecast Data'!C:C,BL$6)+SUMIFS('Forecast Data'!H:H,'Forecast Data'!B:B,D9,'Forecast Data'!C:C,BM$6)+SUMIFS('Forecast Data'!H:H,'Forecast Data'!B:B,D9,'Forecast Data'!C:C,BJ$6))/4 -> 21509.75 | CE9: =IFERROR((SUM(W9:Z9)-(SUMIFS('Forecast Data'!H:H,'Forecast Data'!B:B,D9,'Forecast Data'!C:C,BJ$6)+SUMIFS('Forecast Data'!H:H,'Forecast Data'!B:B,D9,'Forecast Data'!C:C,BK$6)+SUMIFS('Forecast Data'!H:H,'Forecast Data'!B:B,D9,'Forecast Data'!C:C,BL$6)+SUMIFS('Forecast Data'!H:H,'Forecast Data'!B:B,D9,'Forecast Data'!C:C,BM$6)))/(SUMIFS('Forecast Data'!H:H,'Forecast Data'!B:B,D9,'Forecast Data'!C:C,BJ$6)+SUMIFS('Forecast Data'!H:H,'Forecast Data'!B:B,D9,'Forecast Data'!C:C,BK$6)+SUMIFS('Forecast Data'!H:H,'Forecast Data'!B:B,D9,'Forecast Data'!C:C,BL$6)+SUMIFS('Forecast Data'!H:H,'Forecast Data'!B:B,D9,'Forecast Data'!C:C,BM$6)),"") -> 0.27171399 | CF9: =(($L9-$E9)/($L$4-$E$4))*$M$4 -> -0.0004396853 | CG9: =((AVERAGE(W9:Z9)-CD9)/(AVERAGE($W$4:$Z$4)-$CD$4))*$CE$4 -> 0.0048999457 | CH9: =(CF9-CG9)*100 -> -0.5339631
D10: Bath & Body Works | E10: =SUMIFS('Fin Data'!F:F,'Fin Data'!A:A,D10) -> 0 | F10: =SUMIFS('Fin Data with 6 week hist'!I:I,'Fin Data with 6 week hist'!$A:$A,$D10) -> 174 | G10: =SUMIFS('Fin Data with 6 week hist'!J:J,'Fin Data with 6 week hist'!$A:$A,$D10) -> 1556 | H10: =SUMIFS('Fin Data with 6 week hist'!K:K,'Fin Data with 6 week hist'!$A:$A,$D10)+SUMIFS('Unit Cancellations'!D:D,'Unit Cancellations'!$B:$B,$D10) -> 4210 | I10: =SUMIFS('Fin Data with 6 week hist'!L:L,'Fin Data with 6 week hist'!$A:$A,$D10)+SUMIFS('Unit Cancellations'!E:E,'Unit Cancellations'!$B:$B,$D10) -> 5288 | J10: =SUMIFS('Fin Data with 6 week hist'!M:M,'Fin Data with 6 week hist'!$A:$A,$D10)+SUMIFS('Unit Cancellations'!F:F,'Unit Cancellations'!$B:$B,$D10) -> 7186 | K10: =SUMIFS('Fin Data with 6 week hist'!N:N,'Fin Data with 6 week hist'!$A:$A,$D10)+SUMIFS('Unit Cancellations'!G:G,'Unit Cancellations'!$B:$B,$D10) -> 9391 | L10: =SUMIFS('Fin Data'!AN:AN,'Fin Data'!A:A,D10) -> 4634 | M10: =IFERROR(SUMIFS('Fin Data'!AO:AO,'Fin Data'!A:A,D10),"") -> 0 | O10: =AVERAGE(W10:Z10) -> 8125.25 | P10: =CE10 | R10: =AVERAGE(W10:AD10) -> 9512.875 | S10: =BX10 | T10: =AVERAGE(AW10:BD10) -> 0 | U10: =#REF! -> #REF! | W10: =SUMIFS('Forecast Data'!$D:$D,'Forecast Data'!$C:$C,W$6,'Forecast Data'!$B:$B,$D10) -> 8120 | X10: =SUMIFS('Forecast Data'!$D:$D,'Forecast Data'!$C:$C,X$6,'Forecast Data'!$B:$B,$D10) -> 8121 | Y10: =SUMIFS('Forecast Data'!$D:$D,'Forecast Data'!$C:$C,Y$6,'Forecast Data'!$B:$B,$D10) -> 8121 | Z10: =SUMIFS('Forecast Data'!$D:$D,'Forecast Data'!$C:$C,Z$6,'Forecast Data'!$B:$B,$D10) -> 8139 | AA10: =SUMIFS('Forecast Data'!$D:$D,'Forecast Data'!$C:$C,AA$6,'Forecast Data'!$B:$B,$D10) -> 8156 | AB10: =SUMIFS('Forecast Data'!$D:$D,'Forecast Data'!$C:$C,AB$6,'Forecast Data'!$B:$B,$D10) -> 8543 | AC10: =SUMIFS('Forecast Data'!$D:$D,'Forecast Data'!$C:$C,AC$6,'Forecast Data'!$B:$B,$D10) -> 14442 | AD10: =SUMIFS('Forecast Data'!$D:$D,'Forecast Data'!$C:$C,AD$6,'Forecast Data'!$B:$B,$D10) -> 12461 | ... AH10: =SUMIFS('Forecast Data'!$D:$D,'Forecast Data'!$C:$C,AH$6,'Forecast Data'!$B:$B,$D10) -> 9672 | AJ10: =IF(SUMIFS('Forecast Data'!$E:$E,'Forecast Data'!$C:$C,AJ$6,'Forecast Data'!$B:$B,$D10)=0,"",SUMIFS('Forecast Data'!$E:$E,'Forecast Data'!$C:$C,AJ$6,'Forecast Data'!$B:$B,$D10)) | AK10: =IF(SUMIFS('Forecast Data'!$E:$E,'Forecast Data'!$C:$C,AK$6,'Forecast Data'!$B:$B,$D10)=0,"",SUMIFS('Forecast Data'!$E:$E,'Forecast Data'!$C:$C,AK$6,'Forecast Data'!$B:$B,$D10)) | AL10: =IF(SUMIFS('Forecast Data'!$E:$E,'Forecast Data'!$C:$C,AL$6,'Forecast Data'!$B:$B,$D10)=0,"",SUMIFS('Forecast Data'!$E:$E,'Forecast Data'!$C:$C,AL$6,'Forecast Data'!$B:$B,$D10)) | AM10: =IF(SUMIFS('Forecast Data'!$E:$E,'Forecast Data'!$C:$C,AM$6,'Forecast Data'!$B:$B,$D10)=0,"",SUMIFS('Forecast Data'!$E:$E,'Forecast Data'!$C:$C,AM$6,'Forecast Data'!$B:$B,$D10)) | AN10: =IF(SUMIFS('Forecast Data'!$E:$E,'Forecast Data'!$C:$C,AN$6,'Forecast Data'!$B:$B,$D10)=0,"",SUMIFS('Forecast Data'!$E:$E,'Forecast Data'!$C:$C,AN$6,'Forecast Data'!$B:$B,$D10)) | AO10: =IF(SUMIFS('Forecast Data'!$E:$E,'Forecast Data'!$C:$C,AO$6,'Forecast Data'!$B:$B,$D10)=0,"",SUMIFS('Forecast Data'!$E:$E,'Forecast Data'!$C:$C,AO$6,'Forecast Data'!$B:$B,$D10)) | AP10: =IF(SUMIFS('Forecast Data'!$E:$E,'Forecast Data'!$C:$C,AP$6,'Forecast Data'!$B:$B,$D10)=0,"",SUMIFS('Forecast Data'!$E:$E,'Forecast Data'!$C:$C,AP$6,'Forecast Data'!$B:$B,$D10)) | AQ10: =IF(SUMIFS('Forecast Data'!$E:$E,'Forecast Data'!$C:$C,AQ$6,'Forecast Data'!$B:$B,$D10)=0,"",SUMIFS('Forecast Data'!$E:$E,'Forecast Data'!$C:$C,AQ$6,'Forecast Data'!$B:$B,$D10)) | ... AU10: =IF(SUMIFS('Forecast Data'!$E:$E,'Forecast Data'!$C:$C,AU$6,'Forecast Data'!$B:$B,$D10)=0,"",SUMIFS('Forecast Data'!$E:$E,'Forecast Data'!$C:$C,AU$6,'Forecast Data'!$B:$B,$D10)) | AW10: =SUMIFS('OP Units'!E:E,'OP Units'!$A:$A,$D10) -> 0 | AX10: =SUMIFS('OP Units'!F:F,'OP Units'!$A:$A,$D10) -> 0 | AY10: =SUMIFS('OP Units'!G:G,'OP Units'!$A:$A,$D10) -> 0 | AZ10: =SUMIFS('OP Units'!H:H,'OP Units'!$A:$A,$D10) -> 0 | BA10: =SUMIFS('OP Units'!I:I,'OP Units'!$A:$A,$D10) -> 0 | BB10: =SUMIFS('OP Units'!J:J,'OP Units'!$A:$A,$D10) -> 0 | BC10: =SUMIFS('OP Units'!K:K,'OP Units'!$A:$A,$D10) -> 0 | BD10: =SUMIFS('OP Units'!L:L,'OP Units'!$A:$A,$D10) -> 0 | BE10: =SUMIFS('OP Units'!M:M,'OP Units'!$A:$A,$D10) -> 0 | BF10: =SUMIFS('OP Units'!N:N,'OP Units'!$A:$A,$D10) -> 0 | BG10: =SUMIFS('OP Units'!O:O,'OP Units'!$A:$A,$D10) -> 0 | BH10: =SUMIFS('OP Units'!P:P,'OP Units'!$A:$A,$D10) -> 0 | BJ10: =IFERROR((SUMIFS('OP Units'!E:E,'OP Units'!$A:$A,$D10)-SUMIFS('Forecast Data'!$H:$H,'Forecast Data'!$C:$C,BJ$6,'Forecast Data'!$B:$B,$D10))/SUMIFS('Forecast Data'!$H:$H,'Forecast Data'!$C:$C,BJ$6,'Forecast Data'!$B:$B,$D10),"") | BK10: =IFERROR((SUMIFS('OP Units'!F:F,'OP Units'!$A:$A,$D10)-SUMIFS('Forecast Data'!$H:$H,'Forecast Data'!$C:$C,BK$6,'Forecast Data'!$B:$B,$D10))/SUMIFS('Forecast Data'!$H:$H,'Forecast Data'!$C:$C,BK$6,'Forecast Data'!$B:$B,$D10),"") | BL10: =IFERROR((SUMIFS('OP Units'!G:G,'OP Units'!$A:$A,$D10)-SUMIFS('Forecast Data'!$H:$H,'Forecast Data'!$C:$C,BL$6,'Forecast Data'!$B:$B,$D10))/SUMIFS('Forecast Data'!$H:$H,'Forecast Data'!$C:$C,BL$6,'Forecast Data'!$B:$B,$D10),"") | BM10: =IFERROR((SUMIFS('OP Units'!H:H,'OP Units'!$A:$A,$D10)-SUMIFS('Forecast Data'!$H:$H,'Forecast Data'!$C:$C,BM$6,'Forecast Data'!$B:$B,$D10))/SUMIFS('Forecast Data'!$H:$H,'Forecast Data'!$C:$C,BM$6,'Forecast Data'!$B:$B,$D10),"") | BN10: =IFERROR((SUMIFS('OP Units'!I:I,'OP Units'!$A:$A,$D10)-SUMIFS('Forecast Data'!$H:$H,'Forecast Data'!$C:$C,BN$6,'Forecast Data'!$B:$B,$D10))/SUMIFS('Forecast Data'!$H:$H,'Forecast Data'!$C:$C,BN$6,'Forecast Data'!$B:$B,$D10),"") | BO10: =IFERROR((SUMIFS('OP Units'!J:J,'OP Units'!$A:$A,$D10)-SUMIFS('Forecast Data'!$H:$H,'Forecast Data'!$C:$C,BO$6,'Forecast Data'!$B:$B,$D10))/SUMIFS('Forecast Data'!$H:$H,'Forecast Data'!$C:$C,BO$6,'Forecast Data'!$B:$B,$D10),"") | BP10: =IFERROR((SUMIFS('OP Units'!K:K,'OP Units'!$A:$A,$D10)-SUMIFS('Forecast Data'!$H:$H,'Forecast Data'!$C:$C,BP$6,'Forecast Data'!$B:$B,$D10))/SUMIFS('Forecast Data'!$H:$H,'Forecast Data'!$C:$C,BP$6,'Forecast Data'!$B:$B,$D10),"") | BQ10: =IFERROR((SUMIFS('OP Units'!L:L,'OP Units'!$A:$A,$D10)-SUMIFS('Forecast Data'!$H:$H,'Forecast Data'!$C:$C,BQ$6,'Forecast Data'!$B:$B,$D10))/SUMIFS('Forecast Data'!$H:$H,'Forecast Data'!$C:$C,BQ$6,'Forecast Data'!$B:$B,$D10),"") | BR10: =IFERROR((SUMIFS('OP Units'!M:M,'OP Units'!$A:$A,$D10)-SUMIFS('Forecast Data'!$H:$H,'Forecast Data'!$C:$C,BR$6,'Forecast Data'!$B:$B,$D10))/SUMIFS('Forecast Data'!$H:$H,'Forecast Data'!$C:$C,BR$6,'Forecast Data'!$B:$B,$D10),"") | BS10: =IFERROR((SUMIFS('OP Units'!N:N,'OP Units'!$A:$A,$D10)-SUMIFS('Forecast Data'!$H:$H,'Forecast Data'!$C:$C,BS$6,'Forecast Data'!$B:$B,$D10))/SUMIFS('Forecast Data'!$H:$H,'Forecast Data'!$C:$C,BS$6,'Forecast Data'!$B:$B,$D10),"") | BT10: =IFERROR((SUMIFS('OP Units'!O:O,'OP Units'!$A:$A,$D10)-SUMIFS('Forecast Data'!$H:$H,'Forecast Data'!$C:$C,BT$6,'Forecast Data'!$B:$B,$D10))/SUMIFS('Forecast Data'!$H:$H,'Forecast Data'!$C:$C,BT$6,'Forecast Data'!$B:$B,$D10),"") | BU10: =IFERROR((SUMIFS('OP Units'!P:P,'OP Units'!$A:$A,$D10)-SUMIFS('Forecast Data'!$H:$H,'Forecast Data'!$C:$C,BU$6,'Forecast Data'!$B:$B,$D10))/SUMIFS('Forecast Data'!$H:$H,'Forecast Data'!$C:$C,BU$6,'Forecast Data'!$B:$B,$D10),"") | BW10: =(SUMIFS('Forecast Data'!H:H,'Forecast Data'!B:B,D10,'Forecast Data'!C:C,BK$6)+SUMIFS('Forecast Data'!H:H,'Forecast Data'!B:B,D10,'Forecast Data'!C:C,BL$6)+SUMIFS('Forecast Data'!H:H,'Forecast Data'!B:B,D10,'Forecast Data'!C:C,BM$6)+SUMIFS('Forecast Data'!H:H,'Forecast Data'!B:B,D10,'Forecast Data'!C:C,BN$6)+SUMIFS('Forecast Data'!H:H,'Forecast Data'!B:B,D10,'Forecast Data'!C:C,BO$6)+SUMIFS('Forecast Data'!H:H,'Forecast Data'!B:B,D10,'Forecast Data'!C:C,BP$6)+SUMIFS('Forecast Data'!H:H,'Forecast Data'!B:B,D10,'Forecast Data'!C:C,BQ$6)+SUMIFS('Forecast Data'!H:H,'Forecast Data'!B:B,D10,'Forecast Data'!C:C,BJ$6))/8 -> 0 | BX10: =IFERROR((SUM(W10:AD10)-(SUMIFS('Forecast Data'!H:H,'Forecast Data'!B:B,B10,'Forecast Data'!C:C,BJ$6)+SUMIFS('Forecast Data'!H:H,'Forecast Data'!B:B,B10,'Forecast Data'!C:C,BK$6)+SUMIFS('Forecast Data'!H:H,'Forecast Data'!B:B,B10,'Forecast Data'!C:C,BL$6)+SUMIFS('Forecast Data'!H:H,'Forecast Data'!B:B,B10,'Forecast Data'!C:C,BM$6)+SUMIFS('Forecast Data'!H:H,'Forecast Data'!B:B,B10,'Forecast Data'!C:C,BN$6)+SUMIFS('Forecast Data'!H:H,'Forecast Data'!B:B,B10,'Forecast Data'!C:C,BO$6)+SUMIFS('Forecast Data'!H:H,'Forecast Data'!B:B,B10,'Forecast Data'!C:C,BP$6)+SUMIFS('Forecast Data'!H:H,'Forecast Data'!B:B,B10,'Forecast Data'!C:C,BQ$6)))/(SUMIFS('Forecast Data'!H:H,'Forecast Data'!B:B,B10,'Forecast Data'!C:C,BJ$6)+SUMIFS('Forecast Data'!H:H,'Forecast Data'!B:B,B10,'Forecast Data'!C:C,BK$6)+SUMIFS('Forecast Data'!H:H,'Forecast Data'!B:B,B10,'Forecast Data'!C:C,BL$6)+SUMIFS('Forecast Data'!H:H,'Forecast Data'!B:B,B10,'Forecast Data'!C:C,BM$6)+SUMIFS('Forecast Data'!H:H,'Forecast Data'!B:B,B10,'Forecast Data'!C:C,BN$6)+SUMIFS('Forecast Data'!H:H,'Forecast Data'!B:B,B10,'Forecast Data'!C:C,BO$6)+SUMIFS('Forecast Data'!H:H,'Forecast Data'!B:B,B10,'Forecast Data'!C:C,BP$6)+SUMIFS('Forecast Data'!H:H,'Forecast Data'!B:B,B10,'Forecast Data'!C:C,BQ$6)),"") | BY10: =((L10-E10)/($L$4-$E$4))*$M$4 -> 0.0039627261 | BZ10: =((AVERAGE(W10:AD10)-BW10)/(AVERAGE($W$4:$AD$4)-$BW$4))*$BX$4 -> 0.0078224278 | CA10: =(BY10-BZ10)*100 -> -0.38597017 | CB10: =ABS(CA10)/100 -> 0.0038597017 | CD10: =(SUMIFS('Forecast Data'!H:H,'Forecast Data'!B:B,D10,'Forecast Data'!C:C,BK$6)+SUMIFS('Forecast Data'!H:H,'Forecast Data'!B:B,D10,'Forecast Data'!C:C,BL$6)+SUMIFS('Forecast Data'!H:H,'Forecast Data'!B:B,D10,'Forecast Data'!C:C,BM$6)+SUMIFS('Forecast Data'!H:H,'Forecast Data'!B:B,D10,'Forecast Data'!C:C,BJ$6))/4 -> 0 | CE10: =IFERROR((SUM(W10:Z10)-(SUMIFS('Forecast Data'!H:H,'Forecast Data'!B:B,B10,'Forecast Data'!C:C,BJ$6)+SUMIFS('Forecast Data'!H:H,'Forecast Data'!B:B,B10,'Forecast Data'!C:C,BK$6)+SUMIFS('Forecast Data'!H:H,'Forecast Data'!B:B,B10,'Forecast Data'!C:C,BL$6)+SUMIFS('Forecast Data'!H:H,'Forecast Data'!B:B,B10,'Forecast Data'!C:C,BM$6)))/(SUMIFS('Forecast Data'!H:H,'Forecast Data'!B:B,B10,'Forecast Data'!C:C,BJ$6)+SUMIFS('Forecast Data'!H:H,'Forecast Data'!B:B,B10,'Forecast Data'!C:C,BK$6)+SUMIFS('Forecast Data'!H:H,'Forecast Data'!B:B,B10,'Forecast Data'!C:C,BL$6)+SUMIFS('Forecast Data'!H:H,'Forecast Data'!B:B,B10,'Forecast Data'!C:C,BM$6)),"") | CF10: =(($L10-$E10)/($L$4-$E$4))*$M$4 -> 0.0039627261 | CG10: =((AVERAGE(W10:Z10)-CD10)/(AVERAGE($W$4:$Z$4)-$CD$4))*$CE$4 -> 0.0068120941 | CH10: =(CF10-CG10)*100 -> -0.2849368
B11: =D11 -> Youtheory | C11: Holiday | D11: Youtheory | E11: =SUMIFS('Fin Data'!F:F,'Fin Data'!A:A,D11) -> 17051 | F11: =SUMIFS('Fin Data with 6 week hist'!I:I,'Fin Data with 6 week hist'!$A:$A,$D11) -> 19042 | G11: =SUMIFS('Fin Data with 6 week hist'!J:J,'Fin Data with 6 week hist'!$A:$A,$D11) -> 18655 | H11: =SUMIFS('Fin Data with 6 week hist'!K:K,'Fin Data with 6 week hist'!$A:$A,$D11)+SUMIFS('Unit Cancellations'!D:D,'Unit Cancellations'!$B:$B,$D11) -> 19158 | I11: =SUMIFS('Fin Data with 6 week hist'!L:L,'Fin Data with 6 week hist'!$A:$A,$D11)+SUMIFS('Unit Cancellations'!E:E,'Unit Cancellations'!$B:$B,$D11) -> 19064 | J11: =SUMIFS('Fin Data with 6 week hist'!M:M,'Fin Data with 6 week hist'!$A:$A,$D11)+SUMIFS('Unit Cancellations'!F:F,'Unit Cancellations'!$B:$B,$D11) -> 19694 | K11: =SUMIFS('Fin Data with 6 week hist'!N:N,'Fin Data with 6 week hist'!$A:$A,$D11)+SUMIFS('Unit Cancellations'!G:G,'Unit Cancellations'!$B:$B,$D11) -> 19899 | L11: =SUMIFS('Fin Data'!AN:AN,'Fin Data'!A:A,D11) -> 19252.5 | M11: =IFERROR(SUMIFS('Fin Data'!AO:AO,'Fin Data'!A:A,D11),"") -> 0.12911266 | O11: =AVERAGE(W11:Z11) -> 23449.25 | P11: =CE11 -> 0.43631324 | R11: =AVERAGE(W11:AD11) -> 22215.5 | S11: =BX11 -> 0.37412631 | T11: =AVERAGE(AW11:BD11) -> 14043.625 | U11: =#REF! -> #REF! | W11: =SUMIFS('Forecast Data'!$D:$D,'Forecast Data'!$C:$C,W$6,'Forecast Data'!$B:$B,$D11) -> 29395 | X11: =SUMIFS('Forecast Data'!$D:$D,'Forecast Data'!$C:$C,X$6,'Forecast Data'!$B:$B,$D11) -> 22765 | Y11: =SUMIFS('Forecast Data'!$D:$D,'Forecast Data'!$C:$C,Y$6,'Forecast Data'!$B:$B,$D11) -> 20998 | Z11: =SUMIFS('Forecast Data'!$D:$D,'Forecast Data'!$C:$C,Z$6,'Forecast Data'!$B:$B,$D11) -> 20639 | AA11: =SUMIFS('Forecast Data'!$D:$D,'Forecast Data'!$C:$C,AA$6,'Forecast Data'!$B:$B,$D11) -> 20651 | AB11: =SUMIFS('Forecast Data'!$D:$D,'Forecast Data'!$C:$C,AB$6,'Forecast Data'!$B:$B,$D11) -> 21121 | AC11: =SUMIFS('Forecast Data'!$D:$D,'Forecast Data'!$C:$C,AC$6,'Forecast Data'!$B:$B,$D11) -> 21009 | AD11: =SUMIFS('Forecast Data'!$D:$D,'Forecast Data'!$C:$C,AD$6,'Forecast Data'!$B:$B,$D11) -> 21146 | ... AH11: =SUMIFS('Forecast Data'!$D:$D,'Forecast Data'!$C:$C,AH$6,'Forecast Data'!$B:$B,$D11) -> 22162 | AJ11: =IF(SUMIFS('Forecast Data'!$E:$E,'Forecast Data'!$C:$C,AJ$6,'Forecast Data'!$B:$B,$D11)=0,"",SUMIFS('Forecast Data'!$E:$E,'Forecast Data'!$C:$C,AJ$6,'Forecast Data'!$B:$B,$D11)) -> 0.84 | AK11: =IF(SUMIFS('Forecast Data'!$E:$E,'Forecast Data'!$C:$C,AK$6,'Forecast Data'!$B:$B,$D11)=0,"",SUMIFS('Forecast Data'!$E:$E,'Forecast Data'!$C:$C,AK$6,'Forecast Data'!$B:$B,$D11)) -> 0.41 | AL11: =IF(SUMIFS('Forecast Data'!$E:$E,'Forecast Data'!$C:$C,AL$6,'Forecast Data'!$B:$B,$D11)=0,"",SUMIFS('Forecast Data'!$E:$E,'Forecast Data'!$C:$C,AL$6,'Forecast Data'!$B:$B,$D11)) -> 0.28 | AM11: =IF(SUMIFS('Forecast Data'!$E:$E,'Forecast Data'!$C:$C,AM$6,'Forecast Data'!$B:$B,$D11)=0,"",SUMIFS('Forecast Data'!$E:$E,'Forecast Data'!$C:$C,AM$6,'Forecast Data'!$B:$B,$D11)) -> 0.23 | AN11: =IF(SUMIFS('Forecast Data'!$E:$E,'Forecast Data'!$C:$C,AN$6,'Forecast Data'!$B:$B,$D11)=0,"",SUMIFS('Forecast Data'!$E:$E,'Forecast Data'!$C:$C,AN$6,'Forecast Data'!$B:$B,$D11)) -> 0.23 | AO11: =IF(SUMIFS('Forecast Data'!$E:$E,'Forecast Data'!$C:$C,AO$6,'Forecast Data'!$B:$B,$D11)=0,"",SUMIFS('Forecast Data'!$E:$E,'Forecast Data'!$C:$C,AO$6,'Forecast Data'!$B:$B,$D11)) -> 0.34 | AP11: =IF(SUMIFS('Forecast Data'!$E:$E,'Forecast Data'!$C:$C,AP$6,'Forecast Data'!$B:$B,$D11)=0,"",SUMIFS('Forecast Data'!$E:$E,'Forecast Data'!$C:$C,AP$6,'Forecast Data'!$B:$B,$D11)) -> 0.35 | AQ11: =IF(SUMIFS('Forecast Data'!$E:$E,'Forecast Data'!$C:$C,AQ$6,'Forecast Data'!$B:$B,$D11)=0,"",SUMIFS('Forecast Data'!$E:$E,'Forecast Data'!$C:$C,AQ$6,'Forecast Data'!$B:$B,$D11)) -> 0.33 | ... AU11: =IF(SUMIFS('Forecast Data'!$E:$E,'Forecast Data'!$C:$C,AU$6,'Forecast Data'!$B:$B,$D11)=0,"",SUMIFS('Forecast Data'!$E:$E,'Forecast Data'!$C:$C,AU$6,'Forecast Data'!$B:$B,$D11)) -> 0.39 | AW11: =SUMIFS('OP Units'!E:E,'OP Units'!$A:$A,$D11) -> 13755 | AX11: =SUMIFS('OP Units'!F:F,'OP Units'!$A:$A,$D11) -> 15567 | AY11: =SUMIFS('OP Units'!G:G,'OP Units'!$A:$A,$D11) -> 12965 | AZ11: =SUMIFS('OP Units'!H:H,'OP Units'!$A:$A,$D11) -> 12630 | BA11: =SUMIFS('OP Units'!I:I,'OP Units'!$A:$A,$D11) -> 13983 | BB11: =SUMIFS('OP Units'!J:J,'OP Units'!$A:$A,$D11) -> 14931 | BC11: =SUMIFS('OP Units'!K:K,'OP Units'!$A:$A,$D11) -> 14768 | BD11: =SUMIFS('OP Units'!L:L,'OP Units'!$A:$A,$D11) -> 13750 | BE11: =SUMIFS('OP Units'!M:M,'OP Units'!$A:$A,$D11) -> 13171 | BF11: =SUMIFS('OP Units'!N:N,'OP Units'!$A:$A,$D11) -> 12930 | BG11: =SUMIFS('OP Units'!O:O,'OP Units'!$A:$A,$D11) -> 15294 | BH11: =SUMIFS('OP Units'!P:P,'OP Units'!$A:$A,$D11) -> 17408 | BJ11: =IFERROR((SUMIFS('OP Units'!E:E,'OP Units'!$A:$A,$D11)-SUMIFS('Forecast Data'!$H:$H,'Forecast Data'!$C:$C,BJ$6,'Forecast Data'!$B:$B,$D11))/SUMIFS('Forecast Data'!$H:$H,'Forecast Data'!$C:$C,BJ$6,'Forecast Data'!$B:$B,$D11),"") -> -0.13982865 | BK11: =IFERROR((SUMIFS('OP Units'!F:F,'OP Units'!$A:$A,$D11)-SUMIFS('Forecast Data'!$H:$H,'Forecast Data'!$C:$C,BK$6,'Forecast Data'!$B:$B,$D11))/SUMIFS('Forecast Data'!$H:$H,'Forecast Data'!$C:$C,BK$6,'Forecast Data'!$B:$B,$D11),"") -> -0.036099071 | BL11: =IFERROR((SUMIFS('OP Units'!G:G,'OP Units'!$A:$A,$D11)-SUMIFS('Forecast Data'!$H:$H,'Forecast Data'!$C:$C,BL$6,'Forecast Data'!$B:$B,$D11))/SUMIFS('Forecast Data'!$H:$H,'Forecast Data'!$C:$C,BL$6,'Forecast Data'!$B:$B,$D11),"") -> -0.20974034 | BM11: =IFERROR((SUMIFS('OP Units'!H:H,'OP Units'!$A:$A,$D11)-SUMIFS('Forecast Data'!$H:$H,'Forecast Data'!$C:$C,BM$6,'Forecast Data'!$B:$B,$D11))/SUMIFS('Forecast Data'!$H:$H,'Forecast Data'!$C:$C,BM$6,'Forecast Data'!$B:$B,$D11),"") -> -0.24628513 | BN11: =IFERROR((SUMIFS('OP Units'!I:I,'OP Units'!$A:$A,$D11)-SUMIFS('Forecast Data'!$H:$H,'Forecast Data'!$C:$C,BN$6,'Forecast Data'!$B:$B,$D11))/SUMIFS('Forecast Data'!$H:$H,'Forecast Data'!$C:$C,BN$6,'Forecast Data'!$B:$B,$D11),"") -> -0.16509434 | BO11: =IFERROR((SUMIFS('OP Units'!J:J,'OP Units'!$A:$A,$D11)-SUMIFS('Forecast Data'!$H:$H,'Forecast Data'!$C:$C,BO$6,'Forecast Data'!$B:$B,$D11))/SUMIFS('Forecast Data'!$H:$H,'Forecast Data'!$C:$C,BO$6,'Forecast Data'!$B:$B,$D11),"") -> -0.053982133 | BP11: =IFERROR((SUMIFS('OP Units'!K:K,'OP Units'!$A:$A,$D11)-SUMIFS('Forecast Data'!$H:$H,'Forecast Data'!$C:$C,BP$6,'Forecast Data'!$B:$B,$D11))/SUMIFS('Forecast Data'!$H:$H,'Forecast Data'!$C:$C,BP$6,'Forecast Data'!$B:$B,$D11),"") -> -0.050838743 | BQ11: =IFERROR((SUMIFS('OP Units'!L:L,'OP Units'!$A:$A,$D11)-SUMIFS('Forecast Data'!$H:$H,'Forecast Data'!$C:$C,BQ$6,'Forecast Data'!$B:$B,$D11))/SUMIFS('Forecast Data'!$H:$H,'Forecast Data'!$C:$C,BQ$6,'Forecast Data'!$B:$B,$D11),"") -> -0.13749843 | BR11: =IFERROR((SUMIFS('OP Units'!M:M,'OP Units'!$A:$A,$D11)-SUMIFS('Forecast Data'!$H:$H,'Forecast Data'!$C:$C,BR$6,'Forecast Data'!$B:$B,$D11))/SUMIFS('Forecast Data'!$H:$H,'Forecast Data'!$C:$C,BR$6,'Forecast Data'!$B:$B,$D11),"") -> -0.19908787 | BS11: =IFERROR((SUMIFS('OP Units'!N:N,'OP Units'!$A:$A,$D11)-SUMIFS('Forecast Data'!$H:$H,'Forecast Data'!$C:$C,BS$6,'Forecast Data'!$B:$B,$D11))/SUMIFS('Forecast Data'!$H:$H,'Forecast Data'!$C:$C,BS$6,'Forecast Data'!$B:$B,$D11),"") -> -0.20066766 | BT11: =IFERROR((SUMIFS('OP Units'!O:O,'OP Units'!$A:$A,$D11)-SUMIFS('Forecast Data'!$H:$H,'Forecast Data'!$C:$C,BT$6,'Forecast Data'!$B:$B,$D11))/SUMIFS('Forecast Data'!$H:$H,'Forecast Data'!$C:$C,BT$6,'Forecast Data'!$B:$B,$D11),"") -> -0.051358392 | BU11: =IFERROR((SUMIFS('OP Units'!P:P,'OP Units'!$A:$A,$D11)-SUMIFS('Forecast Data'!$H:$H,'Forecast Data'!$C:$C,BU$6,'Forecast Data'!$B:$B,$D11))/SUMIFS('Forecast Data'!$H:$H,'Forecast Data'!$C:$C,BU$6,'Forecast Data'!$B:$B,$D11),"") -> 0.09326132 | BW11: =(SUMIFS('Forecast Data'!H:H,'Forecast Data'!B:B,D11,'Forecast Data'!C:C,BK$6)+SUMIFS('Forecast Data'!H:H,'Forecast Data'!B:B,D11,'Forecast Data'!C:C,BL$6)+SUMIFS('Forecast Data'!H:H,'Forecast Data'!B:B,D11,'Forecast Data'!C:C,BM$6)+SUMIFS('Forecast Data'!H:H,'Forecast Data'!B:B,D11,'Forecast Data'!C:C,BN$6)+SUMIFS('Forecast Data'!H:H,'Forecast Data'!B:B,D11,'Forecast Data'!C:C,BO$6)+SUMIFS('Forecast Data'!H:H,'Forecast Data'!B:B,D11,'Forecast Data'!C:C,BP$6)+SUMIFS('Forecast Data'!H:H,'Forecast Data'!B:B,D11,'Forecast Data'!C:C,BQ$6)+SUMIFS('Forecast Data'!H:H,'Forecast Data'!B:B,D11,'Forecast Data'!C:C,BJ$6))/8 -> 16167 | BX11: =IFERROR((SUM(W11:AD11)-(SUMIFS('Forecast Data'!H:H,'Forecast Data'!B:B,B11,'Forecast Data'!C:C,BJ$6)+SUMIFS('Forecast Data'!H:H,'Forecast Data'!B:B,B11,'Forecast Data'!C:C,BK$6)+SUMIFS('Forecast Data'!H:H,'Forecast Data'!B:B,B11,'Forecast Data'!C:C,BL$6)+SUMIFS('Forecast Data'!H:H,'Forecast Data'!B:B,B11,'Forecast Data'!C:C,BM$6)+SUMIFS('Forecast Data'!H:H,'Forecast Data'!B:B,B11,'Forecast Data'!C:C,BN$6)+SUMIFS('Forecast Data'!H:H,'Forecast Data'!B:B,B11,'Forecast Data'!C:C,BO$6)+SUMIFS('Forecast Data'!H:H,'Forecast Data'!B:B,B11,'Forecast Data'!C:C,BP$6)+SUMIFS('Forecast Data'!H:H,'Forecast Data'!B:B,B11,'Forecast Data'!C:C,BQ$6)))/(SUMIFS('Forecast Data'!H:H,'Forecast Data'!B:B,B11,'Forecast Data'!C:C,BJ$6)+SUMIFS('Forecast Data'!H:H,'Forecast Data'!B:B,B11,'Forecast Data'!C:C,BK$6)+SUMIFS('Forecast Data'!H:H,'Forecast Data'!B:B,B11,'Forecast Data'!C:C,BL$6)+SUMIFS('Forecast Data'!H:H,'Forecast Data'!B:B,B11,'Forecast Data'!C:C,BM$6)+SUMIFS('Forecast Data'!H:H,'Forecast Data'!B:B,B11,'Forecast Data'!C:C,BN$6)+SUMIFS('Forecast Data'!H:H,'Forecast Data'!B:B,B11,'Forecast Data'!C:C,BO$6)+SUMIFS('Forecast Data'!H:H,'Forecast Data'!B:B,B11,'Forecast Data'!C:C,BP$6)+SUMIFS('Forecast Data'!H:H,'Forecast Data'!B:B,B11,'Forecast Data'!C:C,BQ$6)),"") -> 0.37412631 | BY11: =((L11-E11)/($L$4-$E$4))*$M$4 -> 0.0018825942 | BZ11: =((AVERAGE(W11:AD11)-BW11)/(AVERAGE($W$4:$AD$4)-$BW$4))*$BX$4 -> 0.0049736756 | CA11: =(BY11-BZ11)*100 -> -0.30910815 | CB11: =ABS(CA11)/100 -> 0.0030910815 | CD11: =(SUMIFS('Forecast Data'!H:H,'Forecast Data'!B:B,D11,'Forecast Data'!C:C,BK$6)+SUMIFS('Forecast Data'!H:H,'Forecast Data'!B:B,D11,'Forecast Data'!C:C,BL$6)+SUMIFS('Forecast Data'!H:H,'Forecast Data'!B:B,D11,'Forecast Data'!C:C,BM$6)+SUMIFS('Forecast Data'!H:H,'Forecast Data'!B:B,D11,'Forecast Data'!C:C,BJ$6))/4 -> 16326 | CE11: =IFERROR((SUM(W11:Z11)-(SUMIFS('Forecast Data'!H:H,'Forecast Data'!B:B,D11,'Forecast Data'!C:C,BJ$6)+SUMIFS('Forecast Data'!H:H,'Forecast Data'!B:B,D11,'Forecast Data'!C:C,BK$6)+SUMIFS('Forecast Data'!H:H,'Forecast Data'!B:B,D11,'Forecast Data'!C:C,BL$6)+SUMIFS('Forecast Data'!H:H,'Forecast Data'!B:B,D11,'Forecast Data'!C:C,BM$6)))/(SUMIFS('Forecast Data'!H:H,'Forecast Data'!B:B,D11,'Forecast Data'!C:C,BJ$6)+SUMIFS('Forecast Data'!H:H,'Forecast Data'!B:B,D11,'Forecast Data'!C:C,BK$6)+SUMIFS('Forecast Data'!H:H,'Forecast Data'!B:B,D11,'Forecast Data'!C:C,BL$6)+SUMIFS('Forecast Data'!H:H,'Forecast Data'!B:B,D11,'Forecast Data'!C:C,BM$6)),"") -> 0.43631324 | CF11: =(($L11-$E11)/($L$4-$E$4))*$M$4 -> 0.0018825942 | CG11: =((AVERAGE(W11:Z11)-CD11)/(AVERAGE($W$4:$Z$4)-$CD$4))*$CE$4 -> 0.0059720315 | CH11: =(CF11-CG11)*100 -> -0.40894374
